{"task_id": 172, "prediction_id": 0, "generation": "def has_message_body(status):\n    \"\"\"\n    According to the following RFC message body and length SHOULD NOT\n    be included in responses status 1XX, 204 and 304.\n    https://tools.ietf.org/html/rfc2616#section-4.4\n    https://tools.ietf.org/html/rfc2616#section-4.3\n    \"\"\"\n    return status in (200, 204, 304)\n", "message": "failed: Traceback (most recent call last):\n  File \"/codegendata/human-eval/human_eval/execution.py\", line 57, in unsafe_execute\n    exec(check_program, exec_globals)\n  File \"<string>\", line 184, in <module>\n  File \"<string>\", line 183, in test_0\nAssertionError\n", "passed": false}
{"task_id": 172, "prediction_id": 1, "generation": "def has_message_body(status):\n    \"\"\"\n    According to the following RFC message body and length SHOULD NOT\n    be included in responses status 1XX, 204 and 304.\n    https://tools.ietf.org/html/rfc2616#section-4.4\n    https://tools.ietf.org/html/rfc2616#section-4.3\n    \"\"\"\n    return status >= 200 and status < 300 and status != 204 and status != 304\n", "message": "failed: Traceback (most recent call last):\n  File \"/codegendata/human-eval/human_eval/execution.py\", line 57, in unsafe_execute\n    exec(check_program, exec_globals)\n  File \"<string>\", line 184, in <module>\n  File \"<string>\", line 183, in test_0\nAssertionError\n", "passed": false}
{"task_id": 172, "prediction_id": 2, "generation": "def has_message_body(status):\n    \"\"\"\n    According to the following RFC message body and length SHOULD NOT\n    be included in responses status 1XX, 204 and 304.\n    https://tools.ietf.org/html/rfc2616#section-4.4\n    https://tools.ietf.org/html/rfc2616#section-4.3\n    \"\"\"\n    return status not in (200, 204, 304)\n", "message": "failed: Traceback (most recent call last):\n  File \"/codegendata/human-eval/human_eval/execution.py\", line 57, in unsafe_execute\n    exec(check_program, exec_globals)\n  File \"<string>\", line 221, in <module>\n  File \"<string>\", line 220, in test_17\nAssertionError\n", "passed": false}
{"task_id": 172, "prediction_id": 3, "generation": "def has_message_body(status):\n    \"\"\"\n    According to the following RFC message body and length SHOULD NOT\n    be included in responses status 1XX, 204 and 304.\n    https://tools.ietf.org/html/rfc2616#section-4.4\n    https://tools.ietf.org/html/rfc2616#section-4.3\n    \"\"\"\n    return status in (200, 204, 304)\n", "message": "failed: Traceback (most recent call last):\n  File \"/codegendata/human-eval/human_eval/execution.py\", line 57, in unsafe_execute\n    exec(check_program, exec_globals)\n  File \"<string>\", line 184, in <module>\n  File \"<string>\", line 183, in test_0\nAssertionError\n", "passed": false}
{"task_id": 172, "prediction_id": 4, "generation": "def has_message_body(status):\n    \"\"\"\n    According to the following RFC message body and length SHOULD NOT\n    be included in responses status 1XX, 204 and 304.\n    https://tools.ietf.org/html/rfc2616#section-4.4\n    https://tools.ietf.org/html/rfc2616#section-4.3\n    \"\"\"\n    return status in (200, 204, 304)\n", "message": "failed: Traceback (most recent call last):\n  File \"/codegendata/human-eval/human_eval/execution.py\", line 57, in unsafe_execute\n    exec(check_program, exec_globals)\n  File \"<string>\", line 184, in <module>\n  File \"<string>\", line 183, in test_0\nAssertionError\n", "passed": false}
{"task_id": 172, "prediction_id": 5, "generation": "def has_message_body(status):\n    \"\"\"\n    According to the following RFC message body and length SHOULD NOT\n    be included in responses status 1XX, 204 and 304.\n    https://tools.ietf.org/html/rfc2616#section-4.4\n    https://tools.ietf.org/html/rfc2616#section-4.3\n    \"\"\"\n    return status in (200, 204, 304)\n", "message": "failed: Traceback (most recent call last):\n  File \"/codegendata/human-eval/human_eval/execution.py\", line 57, in unsafe_execute\n    exec(check_program, exec_globals)\n  File \"<string>\", line 184, in <module>\n  File \"<string>\", line 183, in test_0\nAssertionError\n", "passed": false}
{"task_id": 172, "prediction_id": 6, "generation": "def has_message_body(status):\n    \"\"\"\n    According to the following RFC message body and length SHOULD NOT\n    be included in responses status 1XX, 204 and 304.\n    https://tools.ietf.org/html/rfc2616#section-4.4\n    https://tools.ietf.org/html/rfc2616#section-4.3\n    \"\"\"\n    return status in (\n        200,\n        201,\n        202,\n        203,\n        204,\n        205,\n        206,\n        207,\n        208,\n        226,\n        300,\n        301,\n        302,\n        303,\n        304,\n        305,\n        307,\n        400,\n        401,\n        402,\n        403,\n        404,\n        405,\n        406,\n        407,\n        408,\n        409,\n        410,\n        411,\n        412,\n        413,\n        414,\n        415,\n        416,\n        417,\n        418,\n        421,\n        422,\n        423,\n        424,\n        425,\n        426,\n        428,\n        429,\n        431,\n        500,\n        501,\n        502,\n        503,\n        504,\n        505,\n        506,\n        507,\n        508,\n        509,\n        510,\n        511,\n    )\n", "message": "failed: Traceback (most recent call last):\n  File \"/codegendata/human-eval/human_eval/execution.py\", line 57, in unsafe_execute\n    exec(check_program, exec_globals)\n  File \"<string>\", line 250, in <module>\n  File \"<string>\", line 249, in test_4\nAssertionError\n", "passed": false}
{"task_id": 172, "prediction_id": 7, "generation": "def has_message_body(status):\n    \"\"\"\n    According to the following RFC message body and length SHOULD NOT\n    be included in responses status 1XX, 204 and 304.\n    https://tools.ietf.org/html/rfc2616#section-4.4\n    https://tools.ietf.org/html/rfc2616#section-4.3\n    \"\"\"\n    return status in [200, 204, 304]\n", "message": "failed: Traceback (most recent call last):\n  File \"/codegendata/human-eval/human_eval/execution.py\", line 57, in unsafe_execute\n    exec(check_program, exec_globals)\n  File \"<string>\", line 184, in <module>\n  File \"<string>\", line 183, in test_0\nAssertionError\n", "passed": false}
{"task_id": 172, "prediction_id": 8, "generation": "def has_message_body(status):\n    \"\"\"\n    According to the following RFC message body and length SHOULD NOT\n    be included in responses status 1XX, 204 and 304.\n    https://tools.ietf.org/html/rfc2616#section-4.4\n    https://tools.ietf.org/html/rfc2616#section-4.3\n    \"\"\"\n    return status in (200, 204, 304)\n", "message": "failed: Traceback (most recent call last):\n  File \"/codegendata/human-eval/human_eval/execution.py\", line 57, in unsafe_execute\n    exec(check_program, exec_globals)\n  File \"<string>\", line 184, in <module>\n  File \"<string>\", line 183, in test_0\nAssertionError\n", "passed": false}
{"task_id": 172, "prediction_id": 9, "generation": "def has_message_body(status):\n    \"\"\"\n    According to the following RFC message body and length SHOULD NOT\n    be included in responses status 1XX, 204 and 304.\n    https://tools.ietf.org/html/rfc2616#section-4.4\n    https://tools.ietf.org/html/rfc2616#section-4.3\n    \"\"\"\n    return status in [200, 204, 304]\n", "message": "failed: Traceback (most recent call last):\n  File \"/codegendata/human-eval/human_eval/execution.py\", line 57, in unsafe_execute\n    exec(check_program, exec_globals)\n  File \"<string>\", line 184, in <module>\n  File \"<string>\", line 183, in test_0\nAssertionError\n", "passed": false}
