{"task_id": 222, "prediction_id": 0, "generation": "def format_task_error(headline, task, command, formatted_exception=None):\n    \"\"\"\n    Format a message body for an error email related to a luigi.task.Task\n\n    :param headline: Summary line for the message\n    :param task: `luigi.task.Task` instance where this error occurred\n    :param formatted_exception: optional string showing traceback\n\n    :return: message body\n    \"\"\"\n    if formatted_exception is None:\n        formatted_exception = wrap_traceback(sys.exc_info()[2])\n    return '%s\\n\\n%s\\n\\n%s' % (headline, command, formatted_exception)\n", "message": "failed: Traceback (most recent call last):\n  File \"/codegendata/human-eval/human_eval/execution.py\", line 57, in unsafe_execute\n    exec(check_program, exec_globals)\n  File \"<string>\", line 417, in <module>\n  File \"<string>\", line 413, in test_extra_0\nAssertionError\n", "passed": false}
{"task_id": 222, "prediction_id": 1, "generation": "def format_task_error(headline, task, command, formatted_exception=None):\n    \"\"\"\n    Format a message body for an error email related to a luigi.task.Task\n\n    :param headline: Summary line for the message\n    :param task: `luigi.task.Task` instance where this error occurred\n    :param formatted_exception: optional string showing traceback\n\n    :return: message body\n    \"\"\"\n    if formatted_exception is None:\n        formatted_exception = wrap_traceback(task.exception())\n    return '%s\\n\\n%s\\n\\n%s' % (headline, command, formatted_exception)\n", "message": "failed: Traceback (most recent call last):\n  File \"/codegendata/human-eval/human_eval/execution.py\", line 57, in unsafe_execute\n    exec(check_program, exec_globals)\n  File \"<string>\", line 381, in <module>\n  File \"<string>\", line 380, in test_2\n  File \"<string>\", line 373, in format_task_error\nAttributeError: 'Task' object has no attribute 'exception'\n", "passed": false}
{"task_id": 222, "prediction_id": 2, "generation": "def format_task_error(headline, task, command, formatted_exception=None):\n    \"\"\"\n    Format a message body for an error email related to a luigi.task.Task\n\n    :param headline: Summary line for the message\n    :param task: `luigi.task.Task` instance where this error occurred\n    :param formatted_exception: optional string showing traceback\n\n    :return: message body\n    \"\"\"\n    if formatted_exception is None:\n        formatted_exception = wrap_traceback(sys.exc_info()[2])\n    return '%s\\n\\n%s\\n\\n%s' % (\n        headline,\n        textwrap.indent(command, '    '),\n        formatted_exception)\n", "message": "failed: Traceback (most recent call last):\n  File \"/codegendata/human-eval/human_eval/execution.py\", line 57, in unsafe_execute\n    exec(check_program, exec_globals)\n  File \"<string>\", line 420, in <module>\n  File \"<string>\", line 416, in test_extra_0\nAssertionError\n", "passed": false}
{"task_id": 222, "prediction_id": 3, "generation": "def format_task_error(headline, task, command, formatted_exception=None):\n    \"\"\"\n    Format a message body for an error email related to a luigi.task.Task\n\n    :param headline: Summary line for the message\n    :param task: `luigi.task.Task` instance where this error occurred\n    :param formatted_exception: optional string showing traceback\n\n    :return: message body\n    \"\"\"\n    if formatted_exception is None:\n        formatted_exception = wrap_traceback(task.exception)\n    message = '%s\\n\\n%s' % (headline, formatted_exception)\n    return message\n", "message": "failed: Traceback (most recent call last):\n  File \"/codegendata/human-eval/human_eval/execution.py\", line 57, in unsafe_execute\n    exec(check_program, exec_globals)\n  File \"<string>\", line 382, in <module>\n  File \"<string>\", line 381, in test_2\n  File \"<string>\", line 373, in format_task_error\nAttributeError: 'Task' object has no attribute 'exception'\n", "passed": false}
{"task_id": 222, "prediction_id": 4, "generation": "def format_task_error(headline, task, command, formatted_exception=None):\n    \"\"\"\n    Format a message body for an error email related to a luigi.task.Task\n\n    :param headline: Summary line for the message\n    :param task: `luigi.task.Task` instance where this error occurred\n    :param formatted_exception: optional string showing traceback\n\n    :return: message body\n    \"\"\"\n    if formatted_exception is None:\n        formatted_exception = wrap_traceback(sys.exc_info()[2])\n    return '%s\\n\\n%s\\n\\n%s' % (headline, command, formatted_exception)\n", "message": "failed: Traceback (most recent call last):\n  File \"/codegendata/human-eval/human_eval/execution.py\", line 57, in unsafe_execute\n    exec(check_program, exec_globals)\n  File \"<string>\", line 417, in <module>\n  File \"<string>\", line 413, in test_extra_0\nAssertionError\n", "passed": false}
{"task_id": 222, "prediction_id": 5, "generation": "def format_task_error(headline, task, command, formatted_exception=None):\n    \"\"\"\n    Format a message body for an error email related to a luigi.task.Task\n\n    :param headline: Summary line for the message\n    :param task: `luigi.task.Task` instance where this error occurred\n    :param formatted_exception: optional string showing traceback\n\n    :return: message body\n    \"\"\"\n    if formatted_exception is None:\n        formatted_exception = wrap_traceback(task.exception)\n    return '%s\\n\\n%s\\n\\n%s' % (headline, formatted_exception, command)\n", "message": "failed: Traceback (most recent call last):\n  File \"/codegendata/human-eval/human_eval/execution.py\", line 57, in unsafe_execute\n    exec(check_program, exec_globals)\n  File \"<string>\", line 381, in <module>\n  File \"<string>\", line 380, in test_2\n  File \"<string>\", line 373, in format_task_error\nAttributeError: 'Task' object has no attribute 'exception'\n", "passed": false}
{"task_id": 222, "prediction_id": 6, "generation": "def format_task_error(headline, task, command, formatted_exception=None):\n    \"\"\"\n    Format a message body for an error email related to a luigi.task.Task\n\n    :param headline: Summary line for the message\n    :param task: `luigi.task.Task` instance where this error occurred\n    :param formatted_exception: optional string showing traceback\n\n    :return: message body\n    \"\"\"\n    if formatted_exception is None:\n        formatted_exception = wrap_traceback(task.exception())\n    return '%s\\n\\n%s\\n\\n%s' % (\n        headline,\n        textwrap.indent(formatted_exception, '    '),\n        command)\n", "message": "failed: Traceback (most recent call last):\n  File \"/codegendata/human-eval/human_eval/execution.py\", line 57, in unsafe_execute\n    exec(check_program, exec_globals)\n  File \"<string>\", line 384, in <module>\n  File \"<string>\", line 383, in test_2\n  File \"<string>\", line 373, in format_task_error\nAttributeError: 'Task' object has no attribute 'exception'\n", "passed": false}
{"task_id": 222, "prediction_id": 7, "generation": "def format_task_error(headline, task, command, formatted_exception=None):\n    \"\"\"\n    Format a message body for an error email related to a luigi.task.Task\n\n    :param headline: Summary line for the message\n    :param task: `luigi.task.Task` instance where this error occurred\n    :param formatted_exception: optional string showing traceback\n\n    :return: message body\n    \"\"\"\n    if formatted_exception is None:\n        formatted_exception = wrap_traceback(sys.exc_info()[2])\n    return '\\n'.join([\n        headline,\n        '\\n'.join(textwrap.wrap(command, width=80)),\n        '\\n' + formatted_exception,\n    ])\n", "message": "failed: Traceback (most recent call last):\n  File \"/codegendata/human-eval/human_eval/execution.py\", line 57, in unsafe_execute\n    exec(check_program, exec_globals)\n  File \"<string>\", line 385, in <module>\n  File \"<string>\", line 384, in test_2\n  File \"<string>\", line 377, in format_task_error\nTypeError: can only concatenate str (not \"NoneType\") to str\n", "passed": false}
{"task_id": 222, "prediction_id": 8, "generation": "def format_task_error(headline, task, command, formatted_exception=None):\n    \"\"\"\n    Format a message body for an error email related to a luigi.task.Task\n\n    :param headline: Summary line for the message\n    :param task: `luigi.task.Task` instance where this error occurred\n    :param formatted_exception: optional string showing traceback\n\n    :return: message body\n    \"\"\"\n    if formatted_exception is None:\n        formatted_exception = wrap_traceback(sys.exc_info()[2])\n    return '%s\\n\\n%s\\n\\n%s' % (\n        headline,\n        command,\n        formatted_exception)\n", "message": "failed: Traceback (most recent call last):\n  File \"/codegendata/human-eval/human_eval/execution.py\", line 57, in unsafe_execute\n    exec(check_program, exec_globals)\n  File \"<string>\", line 420, in <module>\n  File \"<string>\", line 416, in test_extra_0\nAssertionError\n", "passed": false}
{"task_id": 222, "prediction_id": 9, "generation": "def format_task_error(headline, task, command, formatted_exception=None):\n    \"\"\"\n    Format a message body for an error email related to a luigi.task.Task\n\n    :param headline: Summary line for the message\n    :param task: `luigi.task.Task` instance where this error occurred\n    :param formatted_exception: optional string showing traceback\n\n    :return: message body\n    \"\"\"\n    if formatted_exception is None:\n        formatted_exception = wrap_traceback(sys.exc_info()[2])\n    message = '%s\\n\\n%s\\n\\n%s' % (headline, command, formatted_exception)\n    return message\n", "message": "failed: Traceback (most recent call last):\n  File \"/codegendata/human-eval/human_eval/execution.py\", line 57, in unsafe_execute\n    exec(check_program, exec_globals)\n  File \"<string>\", line 418, in <module>\n  File \"<string>\", line 414, in test_extra_0\nAssertionError\n", "passed": false}
