{"task_id": 286, "prediction_id": 0, "generation": "def errno_from_exception(e: BaseException) -> Optional[int]:\n    \"\"\"Provides the errno from an Exception object.\n\n    There are cases that the errno attribute was not set so we pull\n    the errno out of the args but if someone instantiates an Exception\n    without any args you will get a tuple error. So this function\n    abstracts all that behavior to give you a safe way to get the\n    errno.\n    \"\"\"\n    if isinstance(e, tuple):\n        return e[1]\n    return e.errno\n", "message": "failed: Traceback (most recent call last):\n  File \"/codegendata/human-eval/human_eval/execution.py\", line 57, in unsafe_execute\n    exec(check_program, exec_globals)\n  File \"<string>\", line 555, in <module>\n  File \"<string>\", line 554, in test_28\n  File \"<string>\", line 211, in errno_from_exception\nAttributeError: 'Exception' object has no attribute 'errno'\n", "passed": false}
{"task_id": 286, "prediction_id": 1, "generation": "def errno_from_exception(e: BaseException) -> Optional[int]:\n    \"\"\"Provides the errno from an Exception object.\n\n    There are cases that the errno attribute was not set so we pull\n    the errno out of the args but if someone instantiates an Exception\n    without any args you will get a tuple error. So this function\n    abstracts all that behavior to give you a safe way to get the\n    errno.\n    \"\"\"\n    if isinstance(e, tuple):\n        return e[1]\n    return e.errno\n", "message": "failed: Traceback (most recent call last):\n  File \"/codegendata/human-eval/human_eval/execution.py\", line 57, in unsafe_execute\n    exec(check_program, exec_globals)\n  File \"<string>\", line 555, in <module>\n  File \"<string>\", line 554, in test_28\n  File \"<string>\", line 211, in errno_from_exception\nAttributeError: 'Exception' object has no attribute 'errno'\n", "passed": false}
{"task_id": 286, "prediction_id": 2, "generation": "def errno_from_exception(e: BaseException) -> Optional[int]:\n    \"\"\"Provides the errno from an Exception object.\n\n    There are cases that the errno attribute was not set so we pull\n    the errno out of the args but if someone instantiates an Exception\n    without any args you will get a tuple error. So this function\n    abstracts all that behavior to give you a safe way to get the\n    errno.\n    \"\"\"\n    if isinstance(e, tuple):\n        return e[1]\n    if hasattr(e, 'errno'):\n        return e.errno\n    return None\n", "message": "failed: Traceback (most recent call last):\n  File \"/codegendata/human-eval/human_eval/execution.py\", line 57, in unsafe_execute\n    exec(check_program, exec_globals)\n  File \"<string>\", line 557, in <module>\n  File \"<string>\", line 556, in test_28\nAssertionError\n", "passed": false}
{"task_id": 286, "prediction_id": 3, "generation": "def errno_from_exception(e: BaseException) -> Optional[int]:\n    \"\"\"Provides the errno from an Exception object.\n\n    There are cases that the errno attribute was not set so we pull\n    the errno out of the args but if someone instantiates an Exception\n    without any args you will get a tuple error. So this function\n    abstracts all that behavior to give you a safe way to get the\n    errno.\n    \"\"\"\n    if hasattr(e, 'errno'):\n        return e.errno\n    elif isinstance(e, tuple):\n        return e[1]\n    else:\n        return None\n", "message": "failed: Traceback (most recent call last):\n  File \"/codegendata/human-eval/human_eval/execution.py\", line 57, in unsafe_execute\n    exec(check_program, exec_globals)\n  File \"<string>\", line 558, in <module>\n  File \"<string>\", line 557, in test_28\nAssertionError\n", "passed": false}
{"task_id": 286, "prediction_id": 4, "generation": "def errno_from_exception(e: BaseException) -> Optional[int]:\n    \"\"\"Provides the errno from an Exception object.\n\n    There are cases that the errno attribute was not set so we pull\n    the errno out of the args but if someone instantiates an Exception\n    without any args you will get a tuple error. So this function\n    abstracts all that behavior to give you a safe way to get the\n    errno.\n    \"\"\"\n    if hasattr(e, 'errno'):\n        return e.errno\n    elif hasattr(e, 'args'):\n        return e.args[0]\n    else:\n        return None\n", "message": "failed: Traceback (most recent call last):\n  File \"/codegendata/human-eval/human_eval/execution.py\", line 57, in unsafe_execute\n    exec(check_program, exec_globals)\n  File \"<string>\", line 574, in <module>\n  File \"<string>\", line 573, in test_34\n  File \"<string>\", line 212, in errno_from_exception\nIndexError: tuple index out of range\n", "passed": false}
{"task_id": 286, "prediction_id": 5, "generation": "def errno_from_exception(e: BaseException) -> Optional[int]:\n    \"\"\"Provides the errno from an Exception object.\n\n    There are cases that the errno attribute was not set so we pull\n    the errno out of the args but if someone instantiates an Exception\n    without any args you will get a tuple error. So this function\n    abstracts all that behavior to give you a safe way to get the\n    errno.\n    \"\"\"\n    if isinstance(e, tuple):\n        return e[1]\n    return e.errno\n", "message": "failed: Traceback (most recent call last):\n  File \"/codegendata/human-eval/human_eval/execution.py\", line 57, in unsafe_execute\n    exec(check_program, exec_globals)\n  File \"<string>\", line 555, in <module>\n  File \"<string>\", line 554, in test_28\n  File \"<string>\", line 211, in errno_from_exception\nAttributeError: 'Exception' object has no attribute 'errno'\n", "passed": false}
{"task_id": 286, "prediction_id": 6, "generation": "def errno_from_exception(e: BaseException) -> Optional[int]:\n    \"\"\"Provides the errno from an Exception object.\n\n    There are cases that the errno attribute was not set so we pull\n    the errno out of the args but if someone instantiates an Exception\n    without any args you will get a tuple error. So this function\n    abstracts all that behavior to give you a safe way to get the\n    errno.\n    \"\"\"\n    if isinstance(e, tuple):\n        return e[1]\n    return e.errno\n", "message": "failed: Traceback (most recent call last):\n  File \"/codegendata/human-eval/human_eval/execution.py\", line 57, in unsafe_execute\n    exec(check_program, exec_globals)\n  File \"<string>\", line 555, in <module>\n  File \"<string>\", line 554, in test_28\n  File \"<string>\", line 211, in errno_from_exception\nAttributeError: 'Exception' object has no attribute 'errno'\n", "passed": false}
{"task_id": 286, "prediction_id": 7, "generation": "def errno_from_exception(e: BaseException) -> Optional[int]:\n    \"\"\"Provides the errno from an Exception object.\n\n    There are cases that the errno attribute was not set so we pull\n    the errno out of the args but if someone instantiates an Exception\n    without any args you will get a tuple error. So this function\n    abstracts all that behavior to give you a safe way to get the\n    errno.\n    \"\"\"\n    if hasattr(e, 'errno'):\n        return e.errno\n    if isinstance(e, tuple):\n        return None\n    return None\n", "message": "failed: Traceback (most recent call last):\n  File \"/codegendata/human-eval/human_eval/execution.py\", line 57, in unsafe_execute\n    exec(check_program, exec_globals)\n  File \"<string>\", line 557, in <module>\n  File \"<string>\", line 556, in test_28\nAssertionError\n", "passed": false}
{"task_id": 286, "prediction_id": 8, "generation": "def errno_from_exception(e: BaseException) -> Optional[int]:\n    \"\"\"Provides the errno from an Exception object.\n\n    There are cases that the errno attribute was not set so we pull\n    the errno out of the args but if someone instantiates an Exception\n    without any args you will get a tuple error. So this function\n    abstracts all that behavior to give you a safe way to get the\n    errno.\n    \"\"\"\n    try:\n        return e.errno\n    except AttributeError:\n        return None\n", "message": "failed: Traceback (most recent call last):\n  File \"/codegendata/human-eval/human_eval/execution.py\", line 57, in unsafe_execute\n    exec(check_program, exec_globals)\n  File \"<string>\", line 556, in <module>\n  File \"<string>\", line 555, in test_28\nAssertionError\n", "passed": false}
{"task_id": 286, "prediction_id": 9, "generation": "def errno_from_exception(e: BaseException) -> Optional[int]:\n    \"\"\"Provides the errno from an Exception object.\n\n    There are cases that the errno attribute was not set so we pull\n    the errno out of the args but if someone instantiates an Exception\n    without any args you will get a tuple error. So this function\n    abstracts all that behavior to give you a safe way to get the\n    errno.\n    \"\"\"\n    if hasattr(e, 'errno'):\n        return e.errno\n    if hasattr(e, 'args'):\n        if len(e.args) == 1:\n            return e.args[0]\n    return None\n", "message": "failed: Traceback (most recent call last):\n  File \"/codegendata/human-eval/human_eval/execution.py\", line 57, in unsafe_execute\n    exec(check_program, exec_globals)\n  File \"<string>\", line 558, in <module>\n  File \"<string>\", line 557, in test_28\nAssertionError\n", "passed": false}
