{"task_id": 229, "prediction_id": 0, "generation": "def is_magic(name: str) -> bool:\n    \"\"\"Check magic name.\"\"\"\n    return name.startswith('__') and name.endswith('__') and len(name) > 4", "message": "failed: Traceback (most recent call last):\n  File \"/codegendata/human-eval/human_eval/execution.py\", line 57, in unsafe_execute\n    exec(check_program, exec_globals)\n  File \"<string>\", line 637, in <module>\n  File \"<string>\", line 636, in test_3\nAssertionError\n", "passed": false}
{"task_id": 229, "prediction_id": 1, "generation": "def is_magic(name: str) -> bool:\n    \"\"\"Check magic name.\"\"\"\n    # Magic names start and end with double underscores, e.g. __init__, __call__\n    return name.startswith('__') and name.endswith('__') and len(name) > 4", "message": "failed: Traceback (most recent call last):\n  File \"/codegendata/human-eval/human_eval/execution.py\", line 57, in unsafe_execute\n    exec(check_program, exec_globals)\n  File \"<string>\", line 638, in <module>\n  File \"<string>\", line 637, in test_3\nAssertionError\n", "passed": false}
{"task_id": 229, "prediction_id": 2, "generation": "def is_magic(name: str) -> bool:\n    \"\"\"Check magic name.\"\"\"\n    return len(name) > 4 and name.startswith('__') and name.endswith('__')", "message": "failed: Traceback (most recent call last):\n  File \"/codegendata/human-eval/human_eval/execution.py\", line 57, in unsafe_execute\n    exec(check_program, exec_globals)\n  File \"<string>\", line 637, in <module>\n  File \"<string>\", line 636, in test_3\nAssertionError\n", "passed": false}
{"task_id": 229, "prediction_id": 3, "generation": "def is_magic(name: str) -> bool:\n    \"\"\"Check magic name.\"\"\"\n    return name.startswith(\"__\") and name.endswith(\"__\") and len(name) > 4", "message": "failed: Traceback (most recent call last):\n  File \"/codegendata/human-eval/human_eval/execution.py\", line 57, in unsafe_execute\n    exec(check_program, exec_globals)\n  File \"<string>\", line 637, in <module>\n  File \"<string>\", line 636, in test_3\nAssertionError\n", "passed": false}
{"task_id": 229, "prediction_id": 4, "generation": "def is_magic(name: str) -> bool:\n    \"\"\"Check magic name.\"\"\"\n    return name.startswith('__') and name.endswith('__') and len(name) > 4", "message": "failed: Traceback (most recent call last):\n  File \"/codegendata/human-eval/human_eval/execution.py\", line 57, in unsafe_execute\n    exec(check_program, exec_globals)\n  File \"<string>\", line 637, in <module>\n  File \"<string>\", line 636, in test_3\nAssertionError\n", "passed": false}
